Workbook

Sheet Punto de equilibrio
C1: 190102475001
A2: COMPUFACIL COMPUTADORAS Y FACILIDADES CIA.LTDA.
A3: Estado de situación finaciera
C5: 2015 | D5: 2016 | E5: 2017 | F5: 2018 | G5: 2019 | H5: 2020
A6: ACTIVOS
A7: Activos Corrientes:
A8: Efectivo y equivalentes de efectivo | B8: Efectivo_y_equivalentes_de | C8: 3405.75 | D8: 224.8 | E8: 1679.16 | F8: 1271.49 | G8: 56057.07 | H8: 34732.422 | I8: ZONA DE GENERACIÓN DE RIQUEZA
A9: Inversiones financieras C/P | B9: Inversiones_financieras_C_P | C9: 0 | D9: 0 | E9: 0 | F9: 0 | G9: 0 | H9: 0
A10: Cuentas por cobrar | B10: Cuentas_por_cobrar | C10: 130600.21 | D10: 130600.21 | E10: 160768.44 | F10: 143191.27 | G10: 374114.41 | H10: 374446.62
A11: Inventarios | B11: Inventarios | C11: 103701.66 | D11: 93542.172 | E11: 102889.34 | F11: 46753.75 | G11: 584042.44 | H11: 17275
A12: Otros activos corrientes | B12: Otros_activos_corrientes | C12: 13782.57 | D12: 6173.3003 | E12: 9363.7695 | F12: 4844.7998 | G12: 214889.41 | H12: 0
A13: Total activos corrientes | B13: Total_activos_corrientes | C13: 251490.19 | D13: 230540.48 | E13: 274700.7 | F13: 196061.31 | G13: =SUM(G8:G12) -> 1229103.3 | H13: 426454.05
A14: Activos no corrientes:
A15: P.P.E Bruta | B15: P_P_E_Bruta | C15: 63185.219 | D15: 81459.961 | E15: 98117.727 | F15: 119806.72 | G15: 3421246 | H15: 175580.88
A16: Depreciación acumulada | B16: Depreciación_acumulada | C16: -46005.559 | D16: -56861.531 | E16: -65870.141 | F16: -65390.461 | G16: 1250328.2 | H16: -108965.64
A17: P.P.E Neta | B17: P_P_E_Neta | C17: 17179.66 | D17: 24598.43 | E17: 32247.586 | F17: 54416.258 | G17: 217091775 | H17: 66615.234
A18: Inversiones financieras L/P | B18: Inversiones_financieras_L_P | C18: 0 | D18: 0 | E18: 0 | F18: 0 | G18: 0 | H18: 0
A19: Otros activos no corrientes | B19: Otros_activos_no_corrientes | C19: 0 | D19: 0 | E19: 0 | F19: 0 | G19: 43275.45 | H19: 0
A20: Total activos no corrientes | B20: Total_activos_no_corrientes | C20: 17179.66 | D20: 24598.43 | E20: 32247.586 | F20: 54416.258 | G20: 2214193.2 | H20: 66615.234
A21: TOTAL ACTIVOS | B21: TOTAL_ACTIVOS | C21: 268669.85 | D21: 255138.91 | E21: 306948.29 | F21: 250477.56 | G21: 3443296.5 | H21: 493069.28
A22: PASIVO Y CAPITAL
A23: Pasivos corrientes :
A24: Obligaciones financieras de corto plazo | B24: Obligaci_financi_cort_plaz | C24: 0 | D24: 0 | E24: 0 | F24: 42079.461 | G24: 0 | H24: 0
A25: Cuentas por pagar / Proveedores | B25: Cuentas_pagar___Proveedores | C25: 35012.488 | D25: 25586.42 | E25: 18344.4 | F25: 29538.26 | G25: 1083741 | H25: 0
A26: Otros pasivos corrientes | B26: Otros_pasivos_corrientes | C26: 13602.74 | D26: 6035.5498 | E26: 3609.6799 | F26: 6003.46 | G26: 417199.5 | H26: 0
A27: Total pasivos corrientes | B27: Total_pasivos_corrientes | C27: 48615.229 | D27: 31621.97 | E27: 21954.08 | F27: 77621.181 | G27: 1797580.1 | H27: 0
A28: Pasivos no corrientes:
A29: Obligaciones financieras L/P | B29: Obligaciones_financieras_L_P | C29: 92149.758 | D29: 92149.758 | E29: 162287.64 | F29: 58570.281 | G29: 451915.25 | H29: 252430.3
A30: Otros pasivos no corrientes | B30: Otros_pasivos_no_corrientes | C30: 0 | D30: 43011.809 | E30: 36991.031 | F30: 0 | G30: 403256.41 | H30: 0
A31: Total pasivos no corrientes | B31: Total_pasivos_no_corrient | C31: 92149.758 | D31: 135161.57 | E31: 199278.67 | F31: 58570.281 | G31: 855171.62 | H31: 252430.3
A32: Total pasivos | B32: Total_pasivos | C32: 140764.99 | D32: 166783.54 | E32: 221232.75 | F32: 136191.46 | G32: 2652751.8 | H32: 252430.3
A33: Capital :
A34: Capital | B34: Capital | C34: 20680 | D34: 20680 | E34: 20680 | F34: 20680 | G34: 832316 | H34: 20680
A35: Reservas | B35: Reservas_ | C35: 0 | D35: 0 | E35: 0 | F35: 0 | G35: 20995.141 | H35: 0
A36: Utilidades retenidas | B36: Utilidades_retenidas | C36: 96717.773 | D36: 96717.773 | E36: 60657.25 | F36: 65035.539 | G36: -60976.367 | H36: 92757.156
A37: Utilidad del ejercicio | C37: 10507.09 | D37: -29042.4 | E37: 4378.29 | F37: 28570.561 | G37: -1789.72 | H37: 127201.82
A38: Total capital | B38: Total_capital | C38: 127904.86 | D38: 88355.373 | E38: 85715.54 | F38: 114286.1 | G38: 790545.06 | H38: 240638.98
A39: TOTAL PASIVOS Y CAPITAL | B39: TOTAL_PASIVOS_Y_CAPITAL | C39: 268669.85 | D39: 255138.91 | E39: 306948.29 | F39: 250477.56 | G39: 3443296.8 | H39: 493069.27
C40: 0.001953125 | D40: -0.003616333 | E40: 0.0032958984 | F40: -0.0017089844 | G40: 0.0092773438 | H40: -0.0078125
A43: COMPUFACIL COMPUTADORAS Y FACILIDADES CIA.LTDA. | J43: ENFOQUE CONTABILIDAD GERENCIAL
...

Sheet Adminis CxC
A1: ADMINISTRACIÓN DE CUENTAS POR COBRAR
E3: Datos actuales | F3: Cvu (Costo variable unitario) | G3: ='Punto de equilibrio'!N52 -> 35.992521
A4: Datos | F4: Cpu (Costo promedio unitario) | G4: ='Punto de equilibrio'!Q52 -> 40.229432
F5: Pvu (Precio de venta unitario) | G5: 100
A7: Condiciones de crédito actuales | B7: % Descuento ofrecido | C7: 0.08 | E7: Supuesto decisión corto plazo | F7: Quienes aprovechan el Descuento | G7: 0.8
B8: Nuevo plazo de pago | F8: Crecimiento en ventas | G8: 0.15
B9: PMC (Período medio de cobro) | C9: 45 | F9: PMC (Período medio de cobro) | G9: 35 | I9: =25000000/400000 -> 62.5
B10: Ventas a crédito (unidades) | C10: ='Punto de equilibrio'!N106 -> 52353.839 | F10: Gastos cuentas incobrables % | G10: 0.045
B11: Gastos cuentas incobrables % | C11: 0.08 | F11: Rendimiento requerido por la inversión | G11: 0.13
F12: Incremento en ventas (unidades) | G12: =C10*G8 -> 7853.0759
A15: 1) Calcular la Contribución de las Utilidades
A16: a) Método Largo
A17: Plan Propuesto
A18: Ingresos por ventas | C18: =C10+G12 -> 60206.915 | D18: X | E18: =G5 -> 100 | G18: =C18*E18 -> 6020691.5
A19: Menos: | B19: Costos variables | C19: =C10+G12 -> 60206.915 | D19: X | E19: =G3 -> 35.992521 | F19: =C19*E19 -> 2166998.6
B20: Costos Fijos* | F20: =F35*C10 -> 221818.57 | G20: =-(F19+F20) -> -2388817.2
B21: Utilidad sobre ventas | G21: =G18+G20 -> 3631874.3 | H21: =G21/G18 -> 0.60323209
A23: Plan actual
A24: Ingresos por ventas | C24: =C10 -> 52353.839 | D24: X | E24: =G5 -> 100 | G24: =C24*E24 -> 5235383.9
A25: Menos: | B25: Costos variables | C25: =C10 -> 52353.839 | D25: X | E25: =G3 -> 35.992521 | F25: =C25*E25 -> 1884346.6
B26: Costos Fijos* | F26: =F35*C10 -> 221818.57 | G26: =-(F25+F26) -> -2106165.2
B27: Utilidad sobre ventas | G27: =G24+G26 -> 3129218.7 | H27: =G27/G24 -> 0.59770568
B29: Utilidad Marginal en Ventas = Utilidad sobre ventas Plan Propuesto - Utilidad sobre ventas Plan Actual | G29: =G21-G27 -> 502655.59
B31: * Cálculo de los Costos Fijos: | F31: CUP = Costo Unitario Promedio | J31: =C10 -> 52353.839 | K31: =J31*1.12 -> 58636.3
F32: CFU = Costo Fijo Unitario | I32: Costos fijos totales | J32: 25000000 | K32: 25000000
F33: CVU = Costo Variable Unitario
B34: CUP = CFU + CVU ⇒ CFU = CUP − CUV | F34: CFT = Costos Fijos Totales
B35: CFU = | C35: =G4 -> 40.229432 | D35: - | E35: =G3 -> 35.992521 | F35: =C35-E35 -> 4.2369113 | I35: Costos fijos unitarios | J35: =J32/J31 -> 477.5199 | K35: =K32/K31 -> 426.35705
B37: CFT = CFU *UnidadesBA se ⇒
B38: CFT= | C38: =F35 -> 4.2369113 | D38: * | E38: =$C$17 -> 0 | F38: =C38*E38 -> 0 | I38: Costos promedio unitario= | J38: =J40+J44 -> 513.51242 | K38: =K40+K44 -> 462.34957
A40: a) Método abreviado | I40: Costo variable unitario | J40: =G3 -> 35.992521 | K40: =G3 -> 35.992521
B41: Calcular Utilidad Marginal en Ventas ( UMV ) por dos métodos: | I41: Costos variables totales | J41: =J31*J40 -> 1884346.6 | K41: =K31*K40 -> 2110468.2
B43: 1. Por unidad | I43: Costos fijos totales | J43: =J32 -> 25000000 | K43: =K32 -> 25000000
B44: UMV = (PVU − CVU)ΔX | I44: Costos fijos unitarios | J44: =J35 -> 477.5199 | K44: =K35 -> 426.35705
B45: UMV = | C45: =G5 -> 100 | D45: - | E45: =G3 -> 35.992521 | F45: =G12 -> 7853.0759 | G45: =(C45-E45)*F45 -> 502655.59
B47: 2. Por monetario
B48: UMV= [ 1 - (Cvt/Ventas)] Δ Ventas | C48: 1 | D48: - | E48: =F25 -> 1884346.6 | F48: =G18-G24 -> 785307.59 | G48: =(1-(E48/E49))*F48 -> 502655.59
E49: =G24 -> 5235383.9
A51: 2) Calcular el Costo de Inversión Marginal en Cuentas por Cobrar (CIMCC)
A52: a) Cálculo de la Inversión Promedio en Cuentas por Cobrar (IPCC) Plan presente y Plan Propuesto
...
